Workbook

Sheet Curve Header (IEQ use only)
A1: Version 2.0 | C1: Factor | E1: Conversion
A2: =IF('Curve Header Data'!A1="","",'Curve Header Data'!A1) -> Flow: | B2: m3/h | C2: 4.40286764029913 | E2: =IF('Curve Header Data'!B1="USgpm",IF(B2="USgpm",1,1/C2),IF('Curve Header Data'!B1="m3/h",IF(B2="m3/h",1,C2))) -> 0.2271247 | F2: Head | G2: m | H2: 3.28083989501312 | J2: =IF('Curve Header Data'!B2="ft",IF(G2="ft",1,1/H2),IF('Curve Header Data'!B2="m",IF(G2="m",1,H2))) -> 0.3048
A3: =IF('Curve Header Data'!A4="","",'Curve Header Data'!A4) -> Diameter: | B3: mm | C3: 0.039370079 | D3: =IF('Curve Header Data'!D4="","",'Curve Header Data'!D4) | E3: =IF('Curve Header Data'!B4="inch",IF(B3="inch",1,1/C3),IF('Curve Header Data'!B4="mm",IF(B3="mm",1,C3))) -> 25.4 | F3: Power: | G3: kW | H3: 1.3410218586563 | J3: =IF('Curve Header Data'!B3="hp",IF(G3="hp",1,IF(G3="kW",1/H3)),IF('Curve Header Data'!B3="kW",IF(G3="kW",1,IF(G3="hp",H3)))) -> 0.7457
A5: Organization: | B5: Acme
A6: Curve family: | B6: ='Curve Header Data'!B7 -> VT
A7: =IF('Curve Header Data'!A8="","",'Curve Header Data'!A8) | B7: =IF('Curve Header Data'!B8="","",'Curve Header Data'!B8) | E7: curveRevNumber | H7: eyeCount | I7: nssIncrement | O7: headMarginFixedDia | P7: powerDriverFixed | Q7: serviceFactorDriverFixed | R7: speedVariableCurveMin | S7: isoEfficiencyValues
A8: =IF('Curve Header Data'!A9="","",'Curve Header Data'!A9) -> Curve number | B8: =IF('Curve Header Data'!C9="","",'Curve Header Data'!C9) -> Speed, data | C8: =IF('Curve Header Data'!D9="","",'Curve Header Data'!D9) -> Poles | D8: =IF('Curve Header Data'!E9="","",'Curve Header Data'!E9) -> Hz | E8: =IF('Curve Header Data'!B9="","",'Curve Header Data'!B9) -> Revision number | F8: =IF('Curve Header Data'!K9="","",'Curve Header Data'!K9) -> MCSF @ min impeller diameter | G8: =IF('Curve Header Data'!L9="","",'Curve Header Data'!L9) -> MCSF @ max impeller diameter | H8: =IF('Curve Header Data'!N9="","",'Curve Header Data'!N9) -> Number of impeller eyes | I8: =IF('Curve Header Data'!O9="","",'Curve Header Data'!O9) -> Nss Increment | J8: =IF('Curve Header Data'!M9="","",'Curve Header Data'!M9) | K8: =IF('Curve Header Data'!G9="","",'Curve Header Data'!G9) -> Speed, nominal | L8: =IF('Curve Header Data'!H9="","",'Curve Header Data'!H9) -> Speed, Min | M8: =IF('Curve Header Data'!I9="","",'Curve Header Data'!I9) -> Speed, max | N8: =IF('Curve Header Data'!J9="","",'Curve Header Data'!J9) -> Diameter increment | O8: =IF('Curve Header Data'!S9="","",'Curve Header Data'!S9) -> Head margin for fixed diameter | P8: =IF('Curve Header Data'!T9="","",'Curve Header Data'!T9) -> Fixed motor power | Q8: =IF('Curve Header Data'!U9="","",'Curve Header Data'!U9) -> Fixed motor service factor | R8: =IF('Curve Header Data'!V9="","",'Curve Header Data'!V9) -> Variable speed min limit | S8: =IF('Curve Header Data'!W9="","",'Curve Header Data'!W9) -> ISO efficiency values
A9: =IF('Curve Header Data'!A10="","",'Curve Header Data'!A10) | B9: =IF('Curve Header Data'!C10="","",'Curve Header Data'!C10) -> rpm | C9: =IF('Curve Header Data'!D10="","",'Curve Header Data'!D10) | D9: =IF('Curve Header Data'!E10="","",'Curve Header Data'!E10) -> Hz | E9: =IF('Curve Header Data'!B10="","",'Curve Header Data'!B10) | F9: =B2 -> m3/h | G9: =B2 -> m3/h | H9: =IF('Curve Header Data'!N10="","",'Curve Header Data'!N10) | I9: =IF('Curve Header Data'!O10="","",'Curve Header Data'!O10) | J9: =IF('Curve Header Data'!M10="","",'Curve Header Data'!M10) | K9: =IF('Curve Header Data'!G10="","",'Curve Header Data'!G10) -> rpm | L9: =IF('Curve Header Data'!H10="","",'Curve Header Data'!H10) -> rpm | M9: =IF('Curve Header Data'!I10="","",'Curve Header Data'!I10) -> rpm | N9: =B3 -> mm | O9: =G2 -> m | P9: =G3 -> kW | R9: =IF('Curve Header Data'!V10="","",'Curve Header Data'!V10) -> rpm
A10: =IF('Curve Header Data'!A11="","",'Curve Header Data'!A11) | B10: =IF('Curve Header Data'!C11="","",'Curve Header Data'!C11) | C10: =IF('Curve Header Data'!D11="","",'Curve Header Data'!D11) | D10: =IF('Curve Header Data'!E11="","",'Curve Header Data'!E11) | E10: =IF('Curve Header Data'!B11="","",'Curve Header Data'!B11) | F10: =IF('Curve Header Data'!K11="","",'Curve Header Data'!K11*$E$2) | G10: =IF('Curve Header Data'!L11="","",'Curve Header Data'!L11*$E$2) | H10: =IF('Curve Header Data'!N11="","",'Curve Header Data'!N11) -> 1 | I10: =IF('Curve Header Data'!O11="","",'Curve Header Data'!O11) -> 5 | J10: =IF('Curve Header Data'!M11="","",'Curve Header Data'!M11) -> 63 | K10: =IF('Curve Header Data'!G11="","",'Curve Header Data'!G11) | L10: =IF('Curve Header Data'!H11="","",'Curve Header Data'!H11) | M10: =IF('Curve Header Data'!I11="","",'Curve Header Data'!I11) | N10: =IF('Curve Header Data'!J11="","",'Curve Header Data'!J11*$E$3) | O10: =IF('Curve Header Data'!S11="","",'Curve Header Data'!S11*$J$2) -> 0 | P10: =IF('Curve Header Data'!T11="","",'Curve Header Data'!T11*$J$3) -> 0 | Q10: =IF('Curve Header Data'!U11="","",'Curve Header Data'!U11) | R10: =IF('Curve Header Data'!V11="","",'Curve Header Data'!V11) -> 0 | S10: =IF('Curve Header Data'!W11="","",'Curve Header Data'!W11)
A11: =IF('Curve Header Data'!A12="","",'Curve Header Data'!A12) | B11: =IF('Curve Header Data'!C12="","",'Curve Header Data'!C12) | C11: =IF('Curve Header Data'!D12="","",'Curve Header Data'!D12) | D11: =IF('Curve Header Data'!E12="","",'Curve Header Data'!E12) | E11: =IF('Curve Header Data'!B12="","",'Curve Header Data'!B12) | F11: =IF('Curve Header Data'!K12="","",'Curve Header Data'!K12*$E$2) | G11: =IF('Curve Header Data'!L12="","",'Curve Header Data'!L12*$E$2) | H11: =IF('Curve Header Data'!N12="","",'Curve Header Data'!N12) -> 1 | I11: =IF('Curve Header Data'!O12="","",'Curve Header Data'!O12) -> 5 | J11: =IF('Curve Header Data'!M12="","",'Curve Header Data'!M12) | K11: =IF('Curve Header Data'!G12="","",'Curve Header Data'!G12) | L11: =IF('Curve Header Data'!H12="","",'Curve Header Data'!H12) | M11: =IF('Curve Header Data'!I12="","",'Curve Header Data'!I12) | N11: =IF('Curve Header Data'!J12="","",'Curve Header Data'!J12*$E$3) | O11: =IF('Curve Header Data'!S12="","",'Curve Header Data'!S12*$J$2) -> 0 | P11: =IF('Curve Header Data'!T12="","",'Curve Header Data'!T12*$J$3) -> 0 | Q11: =IF('Curve Header Data'!U12="","",'Curve Header Data'!U12) | R11: =IF('Curve Header Data'!V12="","",'Curve Header Data'!V12) -> 0 | S11: =IF('Curve Header Data'!W12="","",'Curve Header Data'!W12)
A12: =IF('Curve Header Data'!A13="","",'Curve Header Data'!A13) | B12: =IF('Curve Header Data'!C13="","",'Curve Header Data'!C13) | C12: =IF('Curve Header Data'!D13="","",'Curve Header Data'!D13) | D12: =IF('Curve Header Data'!E13="","",'Curve Header Data'!E13) | E12: =IF('Curve Header Data'!B13="","",'Curve Header Data'!B13) | F12: =IF('Curve Header Data'!K13="","",'Curve Header Data'!K13*$E$2) | G12: =IF('Curve Header Data'!L13="","",'Curve Header Data'!L13*$E$2) | H12: =IF('Curve Header Data'!N13="","",'Curve Header Data'!N13) -> 1 | I12: =IF('Curve Header Data'!O13="","",'Curve Header Data'!O13) -> 5 | J12: =IF('Curve Header Data'!M13="","",'Curve Header Data'!M13) | K12: =IF('Curve Header Data'!G13="","",'Curve Header Data'!G13) | L12: =IF('Curve Header Data'!H13="","",'Curve Header Data'!H13) | M12: =IF('Curve Header Data'!I13="","",'Curve Header Data'!I13) | N12: =IF('Curve Header Data'!J13="","",'Curve Header Data'!J13*$E$3) | O12: =IF('Curve Header Data'!S13="","",'Curve Header Data'!S13*$J$2) -> 0 | P12: =IF('Curve Header Data'!T13="","",'Curve Header Data'!T13*$J$3) -> 0 | Q12: =IF('Curve Header Data'!U13="","",'Curve Header Data'!U13) | R12: =IF('Curve Header Data'!V13="","",'Curve Header Data'!V13) -> 0 | S12: =IF('Curve Header Data'!W13="","",'Curve Header Data'!W13)
A13: =IF('Curve Header Data'!A14="","",'Curve Header Data'!A14) | B13: =IF('Curve Header Data'!C14="","",'Curve Header Data'!C14) | C13: =IF('Curve Header Data'!D14="","",'Curve Header Data'!D14) | D13: =IF('Curve Header Data'!E14="","",'Curve Header Data'!E14) | E13: =IF('Curve Header Data'!B14="","",'Curve Header Data'!B14) | F13: =IF('Curve Header Data'!K14="","",'Curve Header Data'!K14*$E$2) | G13: =IF('Curve Header Data'!L14="","",'Curve Header Data'!L14*$E$2) | H13: =IF('Curve Header Data'!N14="","",'Curve Header Data'!N14) -> 1 | I13: =IF('Curve Header Data'!O14="","",'Curve Header Data'!O14) -> 5 | J13: =IF('Curve Header Data'!M14="","",'Curve Header Data'!M14) | K13: =IF('Curve Header Data'!G14="","",'Curve Header Data'!G14) | L13: =IF('Curve Header Data'!H14="","",'Curve Header Data'!H14) | M13: =IF('Curve Header Data'!I14="","",'Curve Header Data'!I14) | N13: =IF('Curve Header Data'!J14="","",'Curve Header Data'!J14*$E$3) | O13: =IF('Curve Header Data'!S14="","",'Curve Header Data'!S14*$J$2) -> 0 | P13: =IF('Curve Header Data'!T14="","",'Curve Header Data'!T14*$J$3) -> 0 | Q13: =IF('Curve Header Data'!U14="","",'Curve Header Data'!U14) | R13: =IF('Curve Header Data'!V14="","",'Curve Header Data'!V14) -> 0 | S13: =IF('Curve Header Data'!W14="","",'Curve Header Data'!W14)
A14: =IF('Curve Header Data'!A15="","",'Curve Header Data'!A15) | B14: =IF('Curve Header Data'!C15="","",'Curve Header Data'!C15) | C14: =IF('Curve Header Data'!D15="","",'Curve Header Data'!D15) | D14: =IF('Curve Header Data'!E15="","",'Curve Header Data'!E15) | E14: =IF('Curve Header Data'!B15="","",'Curve Header Data'!B15) | F14: =IF('Curve Header Data'!K15="","",'Curve Header Data'!K15*$E$2) | G14: =IF('Curve Header Data'!L15="","",'Curve Header Data'!L15*$E$2) | H14: =IF('Curve Header Data'!N15="","",'Curve Header Data'!N15) -> 1 | I14: =IF('Curve Header Data'!O15="","",'Curve Header Data'!O15) -> 5 | J14: =IF('Curve Header Data'!M15="","",'Curve Header Data'!M15) | K14: =IF('Curve Header Data'!G15="","",'Curve Header Data'!G15) | L14: =IF('Curve Header Data'!H15="","",'Curve Header Data'!H15) | M14: =IF('Curve Header Data'!I15="","",'Curve Header Data'!I15) | N14: =IF('Curve Header Data'!J15="","",'Curve Header Data'!J15*$E$3) | O14: =IF('Curve Header Data'!S15="","",'Curve Header Data'!S15*$J$2) -> 0 | P14: =IF('Curve Header Data'!T15="","",'Curve Header Data'!T15*$J$3) -> 0 | Q14: =IF('Curve Header Data'!U15="","",'Curve Header Data'!U15) | R14: =IF('Curve Header Data'!V15="","",'Curve Header Data'!V15) -> 0 | S14: =IF('Curve Header Data'!W15="","",'Curve Header Data'!W15)
A15: =IF('Curve Header Data'!A16="","",'Curve Header Data'!A16) | B15: =IF('Curve Header Data'!C16="","",'Curve Header Data'!C16) | C15: =IF('Curve Header Data'!D16="","",'Curve Header Data'!D16) | D15: =IF('Curve Header Data'!E16="","",'Curve Header Data'!E16) | E15: =IF('Curve Header Data'!B16="","",'Curve Header Data'!B16) | F15: =IF('Curve Header Data'!K16="","",'Curve Header Data'!K16*$E$2) | G15: =IF('Curve Header Data'!L16="","",'Curve Header Data'!L16*$E$2) | H15: =IF('Curve Header Data'!N16="","",'Curve Header Data'!N16) -> 1 | I15: =IF('Curve Header Data'!O16="","",'Curve Header Data'!O16) -> 5 | J15: =IF('Curve Header Data'!M16="","",'Curve Header Data'!M16) | K15: =IF('Curve Header Data'!G16="","",'Curve Header Data'!G16) | L15: =IF('Curve Header Data'!H16="","",'Curve Header Data'!H16) | M15: =IF('Curve Header Data'!I16="","",'Curve Header Data'!I16) | N15: =IF('Curve Header Data'!J16="","",'Curve Header Data'!J16*$E$3) | O15: =IF('Curve Header Data'!S16="","",'Curve Header Data'!S16*$J$2) -> 0 | P15: =IF('Curve Header Data'!T16="","",'Curve Header Data'!T16*$J$3) -> 0 | Q15: =IF('Curve Header Data'!U16="","",'Curve Header Data'!U16) | R15: =IF('Curve Header Data'!V16="","",'Curve Header Data'!V16) -> 0 | S15: =IF('Curve Header Data'!W16="","",'Curve Header Data'!W16)
A16: =IF('Curve Header Data'!A17="","",'Curve Header Data'!A17) | B16: =IF('Curve Header Data'!C17="","",'Curve Header Data'!C17) | C16: =IF('Curve Header Data'!D17="","",'Curve Header Data'!D17) | D16: =IF('Curve Header Data'!E17="","",'Curve Header Data'!E17) | E16: =IF('Curve Header Data'!B17="","",'Curve Header Data'!B17) | F16: =IF('Curve Header Data'!K17="","",'Curve Header Data'!K17*$E$2) | G16: =IF('Curve Header Data'!L17="","",'Curve Header Data'!L17*$E$2) | H16: =IF('Curve Header Data'!N17="","",'Curve Header Data'!N17) -> 1 | I16: =IF('Curve Header Data'!O17="","",'Curve Header Data'!O17) -> 5 | J16: =IF('Curve Header Data'!M17="","",'Curve Header Data'!M17) | K16: =IF('Curve Header Data'!G17="","",'Curve Header Data'!G17) | L16: =IF('Curve Header Data'!H17="","",'Curve Header Data'!H17) | M16: =IF('Curve Header Data'!I17="","",'Curve Header Data'!I17) | N16: =IF('Curve Header Data'!J17="","",'Curve Header Data'!J17*$E$3) | O16: =IF('Curve Header Data'!S17="","",'Curve Header Data'!S17*$J$2) -> 0 | P16: =IF('Curve Header Data'!T17="","",'Curve Header Data'!T17*$J$3) -> 0 | Q16: =IF('Curve Header Data'!U17="","",'Curve Header Data'!U17) | R16: =IF('Curve Header Data'!V17="","",'Curve Header Data'!V17) -> 0 | S16: =IF('Curve Header Data'!W17="","",'Curve Header Data'!W17)
A17: =IF('Curve Header Data'!A18="","",'Curve Header Data'!A18) | B17: =IF('Curve Header Data'!C18="","",'Curve Header Data'!C18) | C17: =IF('Curve Header Data'!D18="","",'Curve Header Data'!D18) | D17: =IF('Curve Header Data'!E18="","",'Curve Header Data'!E18) | E17: =IF('Curve Header Data'!B18="","",'Curve Header Data'!B18) | F17: =IF('Curve Header Data'!K18="","",'Curve Header Data'!K18*$E$2) | G17: =IF('Curve Header Data'!L18="","",'Curve Header Data'!L18*$E$2) | H17: =IF('Curve Header Data'!N18="","",'Curve Header Data'!N18) -> 1 | I17: =IF('Curve Header Data'!O18="","",'Curve Header Data'!O18) -> 5 | J17: =IF('Curve Header Data'!M18="","",'Curve Header Data'!M18) | K17: =IF('Curve Header Data'!G18="","",'Curve Header Data'!G18) | L17: =IF('Curve Header Data'!H18="","",'Curve Header Data'!H18) | M17: =IF('Curve Header Data'!I18="","",'Curve Header Data'!I18) | N17: =IF('Curve Header Data'!J18="","",'Curve Header Data'!J18*$E$3) | O17: =IF('Curve Header Data'!S18="","",'Curve Header Data'!S18*$J$2) -> 0 | P17: =IF('Curve Header Data'!T18="","",'Curve Header Data'!T18*$J$3) -> 0 | Q17: =IF('Curve Header Data'!U18="","",'Curve Header Data'!U18) | R17: =IF('Curve Header Data'!V18="","",'Curve Header Data'!V18) -> 0 | S17: =IF('Curve Header Data'!W18="","",'Curve Header Data'!W18)
A18: =IF('Curve Header Data'!A19="","",'Curve Header Data'!A19) | B18: =IF('Curve Header Data'!C19="","",'Curve Header Data'!C19) | C18: =IF('Curve Header Data'!D19="","",'Curve Header Data'!D19) | D18: =IF('Curve Header Data'!E19="","",'Curve Header Data'!E19) | E18: =IF('Curve Header Data'!B19="","",'Curve Header Data'!B19) | F18: =IF('Curve Header Data'!K19="","",'Curve Header Data'!K19*$E$2) | G18: =IF('Curve Header Data'!L19="","",'Curve Header Data'!L19*$E$2) | H18: =IF('Curve Header Data'!N19="","",'Curve Header Data'!N19) -> 1 | I18: =IF('Curve Header Data'!O19="","",'Curve Header Data'!O19) -> 5 | J18: =IF('Curve Header Data'!M19="","",'Curve Header Data'!M19) | K18: =IF('Curve Header Data'!G19="","",'Curve Header Data'!G19) | L18: =IF('Curve Header Data'!H19="","",'Curve Header Data'!H19) | M18: =IF('Curve Header Data'!I19="","",'Curve Header Data'!I19) | N18: =IF('Curve Header Data'!J19="","",'Curve Header Data'!J19*$E$3) | O18: =IF('Curve Header Data'!S19="","",'Curve Header Data'!S19*$J$2) -> 0 | P18: =IF('Curve Header Data'!T19="","",'Curve Header Data'!T19*$J$3) -> 0 | Q18: =IF('Curve Header Data'!U19="","",'Curve Header Data'!U19) | R18: =IF('Curve Header Data'!V19="","",'Curve Header Data'!V19) -> 0 | S18: =IF('Curve Header Data'!W19="","",'Curve Header Data'!W19)
A19: =IF('Curve Header Data'!A20="","",'Curve Header Data'!A20) | B19: =IF('Curve Header Data'!C20="","",'Curve Header Data'!C20) | C19: =IF('Curve Header Data'!D20="","",'Curve Header Data'!D20) | D19: =IF('Curve Header Data'!E20="","",'Curve Header Data'!E20) | E19: =IF('Curve Header Data'!B20="","",'Curve Header Data'!B20) | F19: =IF('Curve Header Data'!K20="","",'Curve Header Data'!K20*$E$2) | G19: =IF('Curve Header Data'!L20="","",'Curve Header Data'!L20*$E$2) | H19: =IF('Curve Header Data'!N20="","",'Curve Header Data'!N20) -> 1 | I19: =IF('Curve Header Data'!O20="","",'Curve Header Data'!O20) -> 5 | J19: =IF('Curve Header Data'!M20="","",'Curve Header Data'!M20) | K19: =IF('Curve Header Data'!G20="","",'Curve Header Data'!G20) | L19: =IF('Curve Header Data'!H20="","",'Curve Header Data'!H20) | M19: =IF('Curve Header Data'!I20="","",'Curve Header Data'!I20) | N19: =IF('Curve Header Data'!J20="","",'Curve Header Data'!J20*$E$3) | O19: =IF('Curve Header Data'!S20="","",'Curve Header Data'!S20*$J$2) -> 0 | P19: =IF('Curve Header Data'!T20="","",'Curve Header Data'!T20*$J$3) -> 0 | Q19: =IF('Curve Header Data'!U20="","",'Curve Header Data'!U20) | R19: =IF('Curve Header Data'!V20="","",'Curve Header Data'!V20) -> 0 | S19: =IF('Curve Header Data'!W20="","",'Curve Header Data'!W20)
A20: =IF('Curve Header Data'!A21="","",'Curve Header Data'!A21) | B20: =IF('Curve Header Data'!C21="","",'Curve Header Data'!C21) | C20: =IF('Curve Header Data'!D21="","",'Curve Header Data'!D21) | D20: =IF('Curve Header Data'!E21="","",'Curve Header Data'!E21) | E20: =IF('Curve Header Data'!B21="","",'Curve Header Data'!B21) | F20: =IF('Curve Header Data'!K21="","",'Curve Header Data'!K21*$E$2) | G20: =IF('Curve Header Data'!L21="","",'Curve Header Data'!L21*$E$2) | H20: =IF('Curve Header Data'!N21="","",'Curve Header Data'!N21) -> 1 | I20: =IF('Curve Header Data'!O21="","",'Curve Header Data'!O21) -> 5 | J20: =IF('Curve Header Data'!M21="","",'Curve Header Data'!M21) | K20: =IF('Curve Header Data'!G21="","",'Curve Header Data'!G21) | L20: =IF('Curve Header Data'!H21="","",'Curve Header Data'!H21) | M20: =IF('Curve Header Data'!I21="","",'Curve Header Data'!I21) | N20: =IF('Curve Header Data'!J21="","",'Curve Header Data'!J21*$E$3) | O20: =IF('Curve Header Data'!S21="","",'Curve Header Data'!S21*$J$2) -> 0 | P20: =IF('Curve Header Data'!T21="","",'Curve Header Data'!T21*$J$3) -> 0 | Q20: =IF('Curve Header Data'!U21="","",'Curve Header Data'!U21) | R20: =IF('Curve Header Data'!V21="","",'Curve Header Data'!V21) -> 0 | S20: =IF('Curve Header Data'!W21="","",'Curve Header Data'!W21)
A21: =IF('Curve Header Data'!A22="","",'Curve Header Data'!A22) | B21: =IF('Curve Header Data'!C22="","",'Curve Header Data'!C22) | C21: =IF('Curve Header Data'!D22="","",'Curve Header Data'!D22) | D21: =IF('Curve Header Data'!E22="","",'Curve Header Data'!E22) | E21: =IF('Curve Header Data'!B22="","",'Curve Header Data'!B22) | F21: =IF('Curve Header Data'!K22="","",'Curve Header Data'!K22*$E$2) | G21: =IF('Curve Header Data'!L22="","",'Curve Header Data'!L22*$E$2) | H21: =IF('Curve Header Data'!N22="","",'Curve Header Data'!N22) -> 1 | I21: =IF('Curve Header Data'!O22="","",'Curve Header Data'!O22) -> 5 | J21: =IF('Curve Header Data'!M22="","",'Curve Header Data'!M22) | K21: =IF('Curve Header Data'!G22="","",'Curve Header Data'!G22) | L21: =IF('Curve Header Data'!H22="","",'Curve Header Data'!H22) | M21: =IF('Curve Header Data'!I22="","",'Curve Header Data'!I22) | N21: =IF('Curve Header Data'!J22="","",'Curve Header Data'!J22*$E$3) | O21: =IF('Curve Header Data'!S22="","",'Curve Header Data'!S22*$J$2) -> 0 | P21: =IF('Curve Header Data'!T22="","",'Curve Header Data'!T22*$J$3) -> 0 | Q21: =IF('Curve Header Data'!U22="","",'Curve Header Data'!U22) | R21: =IF('Curve Header Data'!V22="","",'Curve Header Data'!V22) -> 0 | S21: =IF('Curve Header Data'!W22="","",'Curve Header Data'!W22)
... A307: =IF('Curve Header Data'!A308="","",'Curve Header Data'!A308) | B307: =IF('Curve Header Data'!C308="","",'Curve Header Data'!C308) | C307: =IF('Curve Header Data'!D308="","",'Curve Header Data'!D308) | D307: =IF('Curve Header Data'!E308="","",'Curve Header Data'!E308) | E307: =IF('Curve Header Data'!B308="","",'Curve Header Data'!B308) | F307: =IF('Curve Header Data'!K308="","",'Curve Header Data'!K308*$E$2) | G307: =IF('Curve Header Data'!L308="","",'Curve Header Data'!L308*$E$2) | H307: =IF('Curve Header Data'!N308="","",'Curve Header Data'!N308) -> 1 | I307: =IF('Curve Header Data'!O308="","",'Curve Header Data'!O308) -> 5 | J307: =IF('Curve Header Data'!M308="","",'Curve Header Data'!M308) -> 298 | K307: =IF('Curve Header Data'!G308="","",'Curve Header Data'!G308) | L307: =IF('Curve Header Data'!H308="","",'Curve Header Data'!H308) | M307: =IF('Curve Header Data'!I308="","",'Curve Header Data'!I308) | N307: =IF('Curve Header Data'!J308="","",'Curve Header Data'!J308*$E$3) | O307: =IF('Curve Header Data'!S308="","",'Curve Header Data'!S308*$J$2) | P307: =IF('Curve Header Data'!T308="","",'Curve Header Data'!T308*$J$3) | Q307: =IF('Curve Header Data'!U308="","",'Curve Header Data'!U308) | R307: =IF('Curve Header Data'!V308="","",'Curve Header Data'!V308) | S307: =IF('Curve Header Data'!W308="","",'Curve Header Data'!W308)

Sheet Curve Header Data
A1: Flow: | B1: USgpm | C1: <-- Select your units first.
A2: Head | B2: ft
A3: Power | B3: hp
A4: Diameter: | B4: inch
A7: Curve family: | B7: VT
A9: Curve number | B9: Revision number | C9: Speed, data | D9: Poles | E9: Hz | G9: Speed, nominal | H9: Speed, Min | I9: Speed, max | J9: Diameter increment | K9: MCSF @ min impeller diameter | L9: MCSF @ max impeller diameter | N9: Number of impeller eyes | O9: Nss Increment | P9: Final diameter value strategy | Q9: Display shroud and hub dia | S9: Head margin for fixed diameter | T9: Fixed motor power | U9: Fixed motor service factor | V9: Variable speed min limit | W9: ISO efficiency values
C10: rpm | E10: Hz | G10: rpm | H10: rpm | I10: rpm | J10: =B4 -> inch | K10: =B1 -> USgpm | L10: =B1 -> USgpm | S10: =B2 -> ft | T10: =B3 -> hp | V10: rpm
M11: 63 | N11: 1 | O11: 5 | P11: Round up | Q11: FALSE | S11: 0 | T11: 0 | V11: 0
N12: 1 | O12: 5 | P12: Round up | Q12: FALSE | S12: 0 | T12: 0 | V12: 0
N13: 1 | O13: 5 | P13: Round up | Q13: FALSE | S13: 0 | T13: 0 | V13: 0
N14: 1 | O14: 5 | P14: Round up | Q14: FALSE | S14: 0 | T14: 0 | V14: 0
N15: 1 | O15: 5 | P15: Round up | Q15: FALSE | S15: 0 | T15: 0 | V15: 0
N16: 1 | O16: 5 | P16: Round up | Q16: FALSE | S16: 0 | T16: 0 | V16: 0
N17: 1 | O17: 5 | P17: Round up | Q17: FALSE | S17: 0 | T17: 0 | V17: 0
N18: 1 | O18: 5 | P18: Round up | Q18: FALSE | S18: 0 | T18: 0 | V18: 0
N19: 1 | O19: 5 | P19: Round up | Q19: FALSE | S19: 0 | T19: 0 | V19: 0
N20: 1 | O20: 5 | P20: Round up | Q20: FALSE | S20: 0 | T20: 0 | V20: 0
N21: 1 | O21: 5 | P21: Round up | Q21: FALSE | S21: 0 | T21: 0 | V21: 0
N22: 1 | O22: 5 | P22: Round up | Q22: FALSE | S22: 0 | T22: 0 | V22: 0
N23: 1 | O23: 5 | P23: Round up | Q23: FALSE | S23: 0 | T23: 0 | V23: 0
... N157: 1 | O157: 5 | P157: Round up | Q157: FALSE | S157: 0 | T157: 0 | V157: 0
M158: 148 | N158: 1 | O158: 5 | P158: Round up | Q158: FALSE
M159: 149 | N159: 1 | O159: 5 | P159: Round up | Q159: FALSE
M160: 150 | N160: 1 | O160: 5 | P160: Round up | Q160: FALSE
M161: 151 | N161: 1 | O161: 5 | P161: Round up | Q161: FALSE
M162: 152 | N162: 1 | O162: 5 | P162: Round up | Q162: FALSE
M163: 153 | N163: 1 | O163: 5 | P163: Round up | Q163: FALSE
M164: 154 | N164: 1 | O164: 5 | P164: Round up | Q164: FALSE
M165: 155 | N165: 1 | O165: 5 | P165: Round up | Q165: FALSE
M166: 156 | N166: 1 | O166: 5 | P166: Round up | Q166: FALSE
M167: 157 | N167: 1 | O167: 5 | P167: Round up | Q167: FALSE
M168: 158 | N168: 1 | O168: 5 | P168: Round up | Q168: FALSE
M169: 159 | N169: 1 | O169: 5 | P169: Round up | Q169: FALSE
... M308: 298 | N308: 1 | O308: 5 | P308: Round up | Q308: FALSE

Sheet 10MAHC-2624288
A1: Flow: | B1: USgpm | C1: <-- Select your units first. Then define impeller diameters and NPSH start flow, and then populate the curve point data
A2: Head: | B2: ft
A3: Diameter: | B3: inch | D3: To create additional sheets, use the "Move or Copy" menu. Please do not copy and paste cells from one sheet to another.
A4: Power: | B4: hp | D4: Do not drag and drop cells in this workbook!
A5: Pwr or Eta: | B5: Power
E6: Head start flow | H6: Spline for head | K6: Efficiency start flow | L6: Power start flow | M6: BEP flow | N6: BEP efficiency | O6: Spline for Eta/Pwr | R6: NPSH start flow | S6: Shutoff power | V6: Spline for NPSH | Z6: Head start flow | AF6: Efficiency start flow | AG6: Power start flow | AH6: BEP flow | AI6: BEP efficiency | AM6: NPSH start flow | AN6: Shutoff power | AU6: Head start flow | BA6: Efficiency start flow | BB6: Power start flow | BC6: BEP flow | BD6: BEP efficiency | BH6: NPSH start flow | BI6: Shutoff power | BP6: Head start flow | BV6: Efficiency start flow | BW6: Power start flow | BX6: BEP flow | BY6: BEP efficiency | CC6: NPSH start flow | CD6: Shutoff power | CK6: Head start flow | CQ6: Efficiency start flow | CR6: Power start flow | CS6: BEP flow | CT6: BEP efficiency | CX6: NPSH start flow | CY6: Shutoff power | DF6: Head start flow | DL6: Efficiency start flow | DM6: Power start flow | DN6: BEP flow | DO6: BEP efficiency | DS6: NPSH start flow | DT6: Shutoff power | EA6: Head start flow | EG6: Efficiency start flow | EH6: Power start flow | EI6: BEP flow | EJ6: BEP efficiency | EN6: NPSH start flow | EO6: Shutoff power | EV6: Head start flow | FB6: Efficiency start flow | FC6: Power start flow | FD6: BEP flow | FE6: BEP efficiency | FI6: NPSH start flow | FJ6: Shutoff power | FQ6: Head start flow | FW6: Efficiency start flow | FX6: Power start flow | FY6: BEP flow | FZ6: BEP efficiency | GD6: NPSH start flow | GE6: Shutoff power | GL6: Head start flow | GR6: Efficiency start flow | GS6: Power start flow | GT6: BEP flow | GU6: BEP efficiency | GY6: NPSH start flow | GZ6: Shutoff power | HG6: Head start flow | HM6: Efficiency start flow | HN6: Power start flow | HO6: BEP flow | HP6: BEP efficiency | HT6: NPSH start flow | HU6: Shutoff power | IB6: Head start flow | IH6: Efficiency start flow | II6: Power start flow | IJ6: BEP flow | IK6: BEP efficiency | IO6: NPSH start flow | IP6: Shutoff power
D7: =A10 -> 0 | E7: 0 | H7: FALSE | K7: 0 | L7: 0 | M7: 0 | N7: 0 | O7: FALSE | R7: 0 | V7: FALSE | Y7: =A11 -> 0 | Z7: 0 | AC7: FALSE | AF7: 0 | AG7: 0 | AH7: 0 | AI7: 0 | AJ7: FALSE | AM7: 0 | AQ7: FALSE | AT7: =A12 -> 0 | AU7: 0 | AX7: FALSE | BA7: 0 | BB7: 0 | BC7: 0 | BD7: 0 | BE7: FALSE | BH7: 0 | BL7: FALSE | BO7: =A13 -> 0 | CJ7: =A14 -> 0 | DE7: =A15 -> 0 | DZ7: =A16 -> 0 | EU7: =A17 -> 0 | FP7: =A18 -> 0 | GK7: =A19 -> 0 | HF7: =A20 -> 0 | IA7: =A21 -> 0
A8: Diameter | B8: Hub side dia. | D8: Flow | E8: Head | F8: Disabled | G8: On Curve | H8: Division Point | I8: Slope Enabled | J8: Slope Value | K8: Flow | L8: =$B$5 -> Power | M8: Disabled | N8: On Curve | O8: Division Point | P8: Slope Enabled | Q8: Slope Value | R8: Flow | S8: NPSH | T8: Disabled | U8: On Curve | V8: Division Point | W8: Slope Enabled | X8: Slope Value | Y8: Flow | Z8: Head | AA8: Disabled | AB8: On Curve | AC8: Division Point | AD8: Slope Enabled | AE8: Slope Value | AF8: Flow | AG8: =$B$5 -> Power | AH8: Disabled | AI8: On Curve | AJ8: Division Point | AK8: Slope Enabled | AL8: Slope Value | AM8: Flow | AN8: NPSH | AO8: Disabled | AP8: On Curve | AQ8: Division Point | AR8: Slope Enabled | AS8: Slope Value | AT8: Flow | AU8: Head | AV8: Disabled | AW8: On Curve | AX8: Division Point | AY8: Slope Enabled | AZ8: Slope Value | BA8: Flow | BB8: =$B$5 -> Power | BC8: Disabled | BD8: On Curve | BE8: Division Point | BF8: Slope Enabled | BG8: Slope Value | BH8: Flow | BI8: NPSH | BJ8: Disabled | BK8: On Curve | BL8: Division Point | BM8: Slope Enabled | BN8: Slope Value | BO8: Flow | BP8: Head | BQ8: Disabled | BR8: On Curve | BS8: Division Point | BT8: Slope Enabled | BU8: Slope Value | BV8: Flow | BW8: =$B$5 -> Power | BX8: Disabled | BY8: On Curve | BZ8: Division Point | CA8: Slope Enabled | CB8: Slope Value | CC8: Flow | CD8: NPSH | CE8: Disabled | CF8: On Curve | CG8: Division Point | CH8: Slope Enabled | CI8: Slope Value | CJ8: Flow | CK8: Head | CL8: Disabled | CM8: On Curve | CN8: Division Point | CO8: Slope Enabled | CP8: Slope Value | CQ8: Flow | CR8: =$B$5 -> Power | CS8: Disabled | CT8: On Curve | CU8: Division Point | CV8: Slope Enabled | CW8: Slope Value | CX8: Flow | CY8: NPSH | CZ8: Disabled | DA8: On Curve | DB8: Division Point | DC8: Slope Enabled | DD8: Slope Value | DE8: Flow | DF8: Head | DG8: Disabled | DH8: On Curve | DI8: Division Point | DJ8: Slope Enabled | DK8: Slope Value | DL8: Flow | DM8: =$B$5 -> Power | DN8: Disabled | DO8: On Curve | DP8: Division Point | DQ8: Slope Enabled | DR8: Slope Value | DS8: Flow | DT8: NPSH | DU8: Disabled | DV8: On Curve | DW8: Division Point | DX8: Slope Enabled | DY8: Slope Value | DZ8: Flow | EA8: Head | EB8: Disabled | EC8: On Curve | ED8: Division Point | EE8: Slope Enabled | EF8: Slope Value | EG8: Flow | EH8: =$B$5 -> Power | EI8: Disabled | EJ8: On Curve | EK8: Division Point | EL8: Slope Enabled | EM8: Slope Value | EN8: Flow | EO8: NPSH | EP8: Disabled | EQ8: On Curve | ER8: Division Point | ES8: Slope Enabled | ET8: Slope Value | EU8: Flow | EV8: Head | EW8: Disabled | EX8: On Curve | EY8: Division Point | EZ8: Slope Enabled | FA8: Slope Value | FB8: Flow | FC8: =$B$5 -> Power | FD8: Disabled | FE8: On Curve | FF8: Division Point | FG8: Slope Enabled | FH8: Slope Value | FI8: Flow | FJ8: NPSH | FK8: Disabled | FL8: On Curve | FM8: Division Point | FN8: Slope Enabled | FO8: Slope Value | FP8: Flow | FQ8: Head | FR8: Disabled | FS8: On Curve | FT8: Division Point | FU8: Slope Enabled | FV8: Slope Value | FW8: Flow | FX8: =$B$5 -> Power | FY8: Disabled | FZ8: On Curve | GA8: Division Point | GB8: Slope Enabled | GC8: Slope Value | GD8: Flow | GE8: NPSH | GF8: Disabled | GG8: On Curve | GH8: Division Point | GI8: Slope Enabled | GJ8: Slope Value | GK8: Flow | GL8: Head | GM8: Disabled | GN8: On Curve | GO8: Division Point | GP8: Slope Enabled | GQ8: Slope Value | GR8: Flow | GS8: =$B$5 -> Power | GT8: Disabled | GU8: On Curve | GV8: Division Point | GW8: Slope Enabled | GX8: Slope Value | GY8: Flow | GZ8: NPSH | HA8: Disabled | HB8: On Curve | HC8: Division Point | HD8: Slope Enabled | HE8: Slope Value | HF8: Flow | HG8: Head | HH8: Disabled | HI8: On Curve | HJ8: Division Point | HK8: Slope Enabled | HL8: Slope Value | HM8: Flow | HN8: =$B$5 -> Power | HO8: Disabled | HP8: On Curve | HQ8: Division Point | HR8: Slope Enabled | HS8: Slope Value | HT8: Flow | HU8: NPSH | HV8: Disabled | HW8: On Curve | HX8: Division Point | HY8: Slope Enabled | HZ8: Slope Value | IA8: Flow | IB8: Head | IC8: Disabled | ID8: On Curve | IE8: Division Point | IF8: Slope Enabled | IG8: Slope Value | IH8: Flow | II8: =$B$5 -> Power | IJ8: Disabled | IK8: On Curve | IL8: Division Point | IM8: Slope Enabled | IN8: Slope Value | IO8: Flow | IP8: NPSH | IQ8: Disabled | IR8: On Curve | IS8: Division Point | IT8: Slope Enabled | IU8: Slope Value
A9: =B3 -> inch | B9: =B3 -> inch | D9: =$B$1 -> USgpm | E9: =$B$2 -> ft | K9: =$B$1 -> USgpm | L9: =IF(L8="Eta","%",$B$4) -> hp | R9: =$B$1 -> USgpm | S9: =$B$2 -> ft | Y9: =$B$1 -> USgpm | Z9: =$B$2 -> ft | AF9: =$B$1 -> USgpm | AG9: =IF(AG8="Eta","%",$B$4) -> hp | AM9: =$B$1 -> USgpm | AN9: =$B$2 -> ft | AT9: =$B$1 -> USgpm | AU9: =$B$2 -> ft | BA9: =$B$1 -> USgpm | BB9: =IF(BB8="Eta","%",$B$4) -> hp | BH9: =$B$1 -> USgpm | BI9: =$B$2 -> ft | BO9: =$B$1 -> USgpm | BP9: =$B$2 -> ft | BV9: =$B$1 -> USgpm | BW9: =IF(BW8="Eta","%",$B$4) -> hp | CC9: =$B$1 -> USgpm | CD9: =$B$2 -> ft | CJ9: =$B$1 -> USgpm | CK9: =$B$2 -> ft | CQ9: =$B$1 -> USgpm | CR9: =IF(CR8="Eta","%",$B$4) -> hp | CX9: =$B$1 -> USgpm | CY9: =$B$2 -> ft | DE9: =$B$1 -> USgpm | DF9: =$B$2 -> ft | DL9: =$B$1 -> USgpm | DM9: =IF(DM8="Eta","%",$B$4) -> hp | DS9: =$B$1 -> USgpm | DT9: =$B$2 -> ft | DZ9: =$B$1 -> USgpm | EA9: =$B$2 -> ft | EG9: =$B$1 -> USgpm | EH9: =IF(EH8="Eta","%",$B$4) -> hp | EN9: =$B$1 -> USgpm | EO9: =$B$2 -> ft | EU9: =$B$1 -> USgpm | EV9: =$B$2 -> ft | FB9: =$B$1 -> USgpm | FC9: =IF(FC8="Eta","%",$B$4) -> hp | FI9: =$B$1 -> USgpm | FJ9: =$B$2 -> ft | FP9: =$B$1 -> USgpm | FQ9: =$B$2 -> ft | FW9: =$B$1 -> USgpm | FX9: =IF(FX8="Eta","%",$B$4) -> hp | GD9: =$B$1 -> USgpm | GE9: =$B$2 -> ft | GK9: =$B$1 -> USgpm | GL9: =$B$2 -> ft | GR9: =$B$1 -> USgpm | GS9: =IF(GS8="Eta","%",$B$4) -> hp | GY9: =$B$1 -> USgpm | GZ9: =$B$2 -> ft | HF9: =$B$1 -> USgpm | HG9: =$B$2 -> ft | HM9: =$B$1 -> USgpm | HN9: =IF(HN8="Eta","%",$B$4) -> hp | HT9: =$B$1 -> USgpm | HU9: =$B$2 -> ft | IA9: =$B$1 -> USgpm | IB9: =$B$2 -> ft | IH9: =$B$1 -> USgpm | II9: =IF(II8="Eta","%",$B$4) -> hp | IO9: =$B$1 -> USgpm | IP9: =$B$2 -> ft
C10: 1 | F10: FALSE | G10: FALSE | H10: FALSE | I10: FALSE | M10: FALSE | N10: FALSE | O10: FALSE | P10: FALSE | T10: FALSE | U10: FALSE | V10: FALSE | W10: FALSE | AA10: FALSE | AB10: FALSE | AC10: FALSE | AD10: FALSE | AH10: FALSE | AI10: FALSE | AJ10: FALSE | AK10: FALSE | AO10: FALSE | AP10: FALSE | AQ10: FALSE | AR10: FALSE | AV10: FALSE | AW10: FALSE | AX10: FALSE | AY10: FALSE | BC10: FALSE | BD10: FALSE | BE10: FALSE | BF10: FALSE | BJ10: FALSE | BK10: FALSE | BL10: FALSE | BM10: FALSE | BQ10: FALSE | BR10: FALSE | BS10: FALSE | BT10: FALSE | BX10: FALSE | BY10: FALSE | BZ10: FALSE | CA10: FALSE | CE10: FALSE | CF10: FALSE | CG10: FALSE | CH10: FALSE | CL10: FALSE | CM10: FALSE | CN10: FALSE | CO10: FALSE | CS10: FALSE | CT10: FALSE | CU10: FALSE | CV10: FALSE | CZ10: FALSE | DA10: FALSE | DB10: FALSE | DC10: FALSE | DG10: FALSE | DH10: FALSE | DI10: FALSE | DJ10: FALSE | DN10: FALSE | DO10: FALSE | DP10: FALSE | DQ10: FALSE | DU10: FALSE | DV10: FALSE | DW10: FALSE | DX10: FALSE | EB10: FALSE | EC10: FALSE | ED10: FALSE | EE10: FALSE | EI10: FALSE | EJ10: FALSE | EK10: FALSE | EL10: FALSE | EP10: FALSE | EQ10: FALSE | ER10: FALSE | ES10: FALSE | EW10: FALSE | EX10: FALSE | EY10: FALSE | EZ10: FALSE | FD10: FALSE | FE10: FALSE | FF10: FALSE | FG10: FALSE | FK10: FALSE | FL10: FALSE | FM10: FALSE | FN10: FALSE | FR10: FALSE | FS10: FALSE | FT10: FALSE | FU10: FALSE | FY10: FALSE | FZ10: FALSE | GA10: FALSE | GB10: FALSE | GF10: FALSE | GG10: FALSE | GH10: FALSE | GI10: FALSE | GM10: FALSE | GN10: FALSE | GO10: FALSE | GP10: FALSE | GT10: FALSE | GU10: FALSE | GV10: FALSE | GW10: FALSE | HA10: FALSE | HB10: FALSE | HC10: FALSE | HD10: FALSE | HH10: FALSE | HI10: FALSE | HJ10: FALSE | HK10: FALSE | HO10: FALSE | HP10: FALSE | HQ10: FALSE | HR10: FALSE | HV10: FALSE | HW10: FALSE | HX10: FALSE | HY10: FALSE | IC10: FALSE | ID10: FALSE | IE10: FALSE | IF10: FALSE | IJ10: FALSE | IK10: FALSE | IL10: FALSE | IM10: FALSE | IQ10: FALSE | IR10: FALSE | IS10: FALSE | IT10: FALSE
C11: 2 | F11: FALSE | G11: FALSE | H11: FALSE | I11: FALSE | M11: FALSE | N11: FALSE | O11: FALSE | P11: FALSE | T11: FALSE | U11: FALSE | V11: FALSE | W11: FALSE | AA11: FALSE | AB11: FALSE | AC11: FALSE | AD11: FALSE | AH11: FALSE | AI11: FALSE | AJ11: FALSE | AK11: FALSE | AO11: FALSE | AP11: FALSE | AQ11: FALSE | AR11: FALSE | AV11: FALSE | AW11: FALSE | AX11: FALSE | AY11: FALSE | BC11: FALSE | BD11: FALSE | BE11: FALSE | BF11: FALSE | BJ11: FALSE | BK11: FALSE | BL11: FALSE | BM11: FALSE | BQ11: FALSE | BR11: FALSE | BS11: FALSE | BT11: FALSE | BX11: FALSE | BY11: FALSE | BZ11: FALSE | CA11: FALSE | CE11: FALSE | CF11: FALSE | CG11: FALSE | CH11: FALSE | CL11: FALSE | CM11: FALSE | CN11: FALSE | CO11: FALSE | CS11: FALSE | CT11: FALSE | CU11: FALSE | CV11: FALSE | CZ11: FALSE | DA11: FALSE | DB11: FALSE | DC11: FALSE | DG11: FALSE | DH11: FALSE | DI11: FALSE | DJ11: FALSE | DN11: FALSE | DO11: FALSE | DP11: FALSE | DQ11: FALSE | DU11: FALSE | DV11: FALSE | DW11: FALSE | DX11: FALSE | EB11: FALSE | EC11: FALSE | ED11: FALSE | EE11: FALSE | EI11: FALSE | EJ11: FALSE | EK11: FALSE | EL11: FALSE | EP11: FALSE | EQ11: FALSE | ER11: FALSE | ES11: FALSE | EW11: FALSE | EX11: FALSE | EY11: FALSE | EZ11: FALSE | FD11: FALSE | FE11: FALSE | FF11: FALSE | FG11: FALSE | FK11: FALSE | FL11: FALSE | FM11: FALSE | FN11: FALSE | FR11: FALSE | FS11: FALSE | FT11: FALSE | FU11: FALSE | FY11: FALSE | FZ11: FALSE | GA11: FALSE | GB11: FALSE | GF11: FALSE | GG11: FALSE | GH11: FALSE | GI11: FALSE | GM11: FALSE | GN11: FALSE | GO11: FALSE | GP11: FALSE | GT11: FALSE | GU11: FALSE | GV11: FALSE | GW11: FALSE | HA11: FALSE | HB11: FALSE | HC11: FALSE | HD11: FALSE | HH11: FALSE | HI11: FALSE | HJ11: FALSE | HK11: FALSE | HO11: FALSE | HP11: FALSE | HQ11: FALSE | HR11: FALSE | HV11: FALSE | HW11: FALSE | HX11: FALSE | HY11: FALSE | IC11: FALSE | ID11: FALSE | IE11: FALSE | IF11: FALSE | IJ11: FALSE | IK11: FALSE | IL11: FALSE | IM11: FALSE | IQ11: FALSE | IR11: FALSE | IS11: FALSE | IT11: FALSE
C12: 3 | F12: FALSE | G12: FALSE | H12: FALSE | I12: FALSE | M12: FALSE | N12: FALSE | O12: FALSE | P12: FALSE | T12: FALSE | U12: FALSE | V12: FALSE | W12: FALSE | AA12: FALSE | AB12: FALSE | AC12: FALSE | AD12: FALSE | AH12: FALSE | AI12: FALSE | AJ12: FALSE | AK12: FALSE | AO12: FALSE | AP12: FALSE | AQ12: FALSE | AR12: FALSE | AV12: FALSE | AW12: FALSE | AX12: FALSE | AY12: FALSE | BC12: FALSE | BD12: FALSE | BE12: FALSE | BF12: FALSE | BJ12: FALSE | BK12: FALSE | BL12: FALSE | BM12: FALSE | BQ12: FALSE | BR12: FALSE | BS12: FALSE | BT12: FALSE | BX12: FALSE | BY12: FALSE | BZ12: FALSE | CA12: FALSE | CE12: FALSE | CF12: FALSE | CG12: FALSE | CH12: FALSE | CL12: FALSE | CM12: FALSE | CN12: FALSE | CO12: FALSE | CS12: FALSE | CT12: FALSE | CU12: FALSE | CV12: FALSE | CZ12: FALSE | DA12: FALSE | DB12: FALSE | DC12: FALSE | DG12: FALSE | DH12: FALSE | DI12: FALSE | DJ12: FALSE | DN12: FALSE | DO12: FALSE | DP12: FALSE | DQ12: FALSE | DU12: FALSE | DV12: FALSE | DW12: FALSE | DX12: FALSE | EB12: FALSE | EC12: FALSE | ED12: FALSE | EE12: FALSE | EI12: FALSE | EJ12: FALSE | EK12: FALSE | EL12: FALSE | EP12: FALSE | EQ12: FALSE | ER12: FALSE | ES12: FALSE | EW12: FALSE | EX12: FALSE | EY12: FALSE | EZ12: FALSE | FD12: FALSE | FE12: FALSE | FF12: FALSE | FG12: FALSE | FK12: FALSE | FL12: FALSE | FM12: FALSE | FN12: FALSE | FR12: FALSE | FS12: FALSE | FT12: FALSE | FU12: FALSE | FY12: FALSE | FZ12: FALSE | GA12: FALSE | GB12: FALSE | GF12: FALSE | GG12: FALSE | GH12: FALSE | GI12: FALSE | GM12: FALSE | GN12: FALSE | GO12: FALSE | GP12: FALSE | GT12: FALSE | GU12: FALSE | GV12: FALSE | GW12: FALSE | HA12: FALSE | HB12: FALSE | HC12: FALSE | HD12: FALSE | HH12: FALSE | HI12: FALSE | HJ12: FALSE | HK12: FALSE | HO12: FALSE | HP12: FALSE | HQ12: FALSE | HR12: FALSE | HV12: FALSE | HW12: FALSE | HX12: FALSE | HY12: FALSE | IC12: FALSE | ID12: FALSE | IE12: FALSE | IF12: FALSE | IJ12: FALSE | IK12: FALSE | IL12: FALSE | IM12: FALSE | IQ12: FALSE | IR12: FALSE | IS12: FALSE | IT12: FALSE
C13: 4 | F13: FALSE | G13: FALSE | H13: FALSE | I13: FALSE | M13: FALSE | N13: FALSE | O13: FALSE | P13: FALSE | T13: FALSE | U13: FALSE | V13: FALSE | W13: FALSE | AA13: FALSE | AB13: FALSE | AC13: FALSE | AD13: FALSE | AH13: FALSE | AI13: FALSE | AJ13: FALSE | AK13: FALSE | AO13: FALSE | AP13: FALSE | AQ13: FALSE | AR13: FALSE | AV13: FALSE | AW13: FALSE | AX13: FALSE | AY13: FALSE | BC13: FALSE | BD13: FALSE | BE13: FALSE | BF13: FALSE | BJ13: FALSE | BK13: FALSE | BL13: FALSE | BM13: FALSE | BQ13: FALSE | BR13: FALSE | BS13: FALSE | BT13: FALSE | BX13: FALSE | BY13: FALSE | BZ13: FALSE | CA13: FALSE | CE13: FALSE | CF13: FALSE | CG13: FALSE | CH13: FALSE | CL13: FALSE | CM13: FALSE | CN13: FALSE | CO13: FALSE | CS13: FALSE | CT13: FALSE | CU13: FALSE | CV13: FALSE | CZ13: FALSE | DA13: FALSE | DB13: FALSE | DC13: FALSE | DG13: FALSE | DH13: FALSE | DI13: FALSE | DJ13: FALSE | DN13: FALSE | DO13: FALSE | DP13: FALSE | DQ13: FALSE | DU13: FALSE | DV13: FALSE | DW13: FALSE | DX13: FALSE | EB13: FALSE | EC13: FALSE | ED13: FALSE | EE13: FALSE | EI13: FALSE | EJ13: FALSE | EK13: FALSE | EL13: FALSE | EP13: FALSE | EQ13: FALSE | ER13: FALSE | ES13: FALSE | EW13: FALSE | EX13: FALSE | EY13: FALSE | EZ13: FALSE | FD13: FALSE | FE13: FALSE | FF13: FALSE | FG13: FALSE | FK13: FALSE | FL13: FALSE | FM13: FALSE | FN13: FALSE | FR13: FALSE | FS13: FALSE | FT13: FALSE | FU13: FALSE | FY13: FALSE | FZ13: FALSE | GA13: FALSE | GB13: FALSE | GF13: FALSE | GG13: FALSE | GH13: FALSE | GI13: FALSE | GM13: FALSE | GN13: FALSE | GO13: FALSE | GP13: FALSE | GT13: FALSE | GU13: FALSE | GV13: FALSE | GW13: FALSE | HA13: FALSE | HB13: FALSE | HC13: FALSE | HD13: FALSE | HH13: FALSE | HI13: FALSE | HJ13: FALSE | HK13: FALSE | HO13: FALSE | HP13: FALSE | HQ13: FALSE | HR13: FALSE | HV13: FALSE | HW13: FALSE | HX13: FALSE | HY13: FALSE | IC13: FALSE | ID13: FALSE | IE13: FALSE | IF13: FALSE | IJ13: FALSE | IK13: FALSE | IL13: FALSE | IM13: FALSE | IQ13: FALSE | IR13: FALSE | IS13: FALSE | IT13: FALSE
C14: 5 | F14: FALSE | G14: FALSE | H14: FALSE | I14: FALSE | M14: FALSE | N14: FALSE | O14: FALSE | P14: FALSE | T14: FALSE | U14: FALSE | V14: FALSE | W14: FALSE | AA14: FALSE | AB14: FALSE | AC14: FALSE | AD14: FALSE | AH14: FALSE | AI14: FALSE | AJ14: FALSE | AK14: FALSE | AO14: FALSE | AP14: FALSE | AQ14: FALSE | AR14: FALSE | AV14: FALSE | AW14: FALSE | AX14: FALSE | AY14: FALSE | BC14: FALSE | BD14: FALSE | BE14: FALSE | BF14: FALSE | BJ14: FALSE | BK14: FALSE | BL14: FALSE | BM14: FALSE | BQ14: FALSE | BR14: FALSE | BS14: FALSE | BT14: FALSE | BX14: FALSE | BY14: FALSE | BZ14: FALSE | CA14: FALSE | CE14: FALSE | CF14: FALSE | CG14: FALSE | CH14: FALSE | CL14: FALSE | CM14: FALSE | CN14: FALSE | CO14: FALSE | CS14: FALSE | CT14: FALSE | CU14: FALSE | CV14: FALSE | CZ14: FALSE | DA14: FALSE | DB14: FALSE | DC14: FALSE | DG14: FALSE | DH14: FALSE | DI14: FALSE | DJ14: FALSE | DN14: FALSE | DO14: FALSE | DP14: FALSE | DQ14: FALSE | DU14: FALSE | DV14: FALSE | DW14: FALSE | DX14: FALSE | EB14: FALSE | EC14: FALSE | ED14: FALSE | EE14: FALSE | EI14: FALSE | EJ14: FALSE | EK14: FALSE | EL14: FALSE | EP14: FALSE | EQ14: FALSE | ER14: FALSE | ES14: FALSE | EW14: FALSE | EX14: FALSE | EY14: FALSE | EZ14: FALSE | FD14: FALSE | FE14: FALSE | FF14: FALSE | FG14: FALSE | FK14: FALSE | FL14: FALSE | FM14: FALSE | FN14: FALSE | FR14: FALSE | FS14: FALSE | FT14: FALSE | FU14: FALSE | FY14: FALSE | FZ14: FALSE | GA14: FALSE | GB14: FALSE | GF14: FALSE | GG14: FALSE | GH14: FALSE | GI14: FALSE | GM14: FALSE | GN14: FALSE | GO14: FALSE | GP14: FALSE | GT14: FALSE | GU14: FALSE | GV14: FALSE | GW14: FALSE | HA14: FALSE | HB14: FALSE | HC14: FALSE | HD14: FALSE | HH14: FALSE | HI14: FALSE | HJ14: FALSE | HK14: FALSE | HO14: FALSE | HP14: FALSE | HQ14: FALSE | HR14: FALSE | HV14: FALSE | HW14: FALSE | HX14: FALSE | HY14: FALSE | IC14: FALSE | ID14: FALSE | IE14: FALSE | IF14: FALSE | IJ14: FALSE | IK14: FALSE | IL14: FALSE | IM14: FALSE | IQ14: FALSE | IR14: FALSE | IS14: FALSE | IT14: FALSE
C15: 6 | F15: FALSE | G15: FALSE | H15: FALSE | I15: FALSE | M15: FALSE | N15: FALSE | O15: FALSE | P15: FALSE | T15: FALSE | U15: FALSE | V15: FALSE | W15: FALSE | AA15: FALSE | AB15: FALSE | AC15: FALSE | AD15: FALSE | AH15: FALSE | AI15: FALSE | AJ15: FALSE | AK15: FALSE | AO15: FALSE | AP15: FALSE | AQ15: FALSE | AR15: FALSE | AV15: FALSE | AW15: TRUE | AX15: TRUE | AY15: FALSE | BC15: FALSE | BD15: FALSE | BE15: FALSE | BF15: FALSE | BJ15: FALSE | BK15: FALSE | BL15: FALSE | BM15: FALSE | BQ15: FALSE | BR15: FALSE | BS15: FALSE | BT15: FALSE | BX15: FALSE | BY15: FALSE | BZ15: FALSE | CA15: FALSE | CE15: FALSE | CF15: FALSE | CG15: FALSE | CH15: FALSE | CL15: FALSE | CM15: FALSE | CN15: FALSE | CO15: FALSE | CS15: FALSE | CT15: FALSE | CU15: FALSE | CV15: FALSE | CZ15: FALSE | DA15: FALSE | DB15: FALSE | DC15: FALSE | DG15: FALSE | DH15: FALSE | DI15: FALSE | DJ15: FALSE | DN15: FALSE | DO15: FALSE | DP15: FALSE | DQ15: FALSE | DU15: FALSE | DV15: FALSE | DW15: FALSE | DX15: FALSE | EB15: FALSE | EC15: FALSE | ED15: FALSE | EE15: FALSE | EI15: FALSE | EJ15: FALSE | EK15: FALSE | EL15: FALSE | EP15: FALSE | EQ15: FALSE | ER15: FALSE | ES15: FALSE | EW15: FALSE | EX15: FALSE | EY15: FALSE | EZ15: FALSE | FD15: FALSE | FE15: FALSE | FF15: FALSE | FG15: FALSE | FK15: FALSE | FL15: FALSE | FM15: FALSE | FN15: FALSE | FR15: FALSE | FS15: FALSE | FT15: FALSE | FU15: FALSE | FY15: FALSE | FZ15: FALSE | GA15: FALSE | GB15: FALSE | GF15: FALSE | GG15: FALSE | GH15: FALSE | GI15: FALSE | GM15: FALSE | GN15: FALSE | GO15: FALSE | GP15: FALSE | GT15: FALSE | GU15: FALSE | GV15: FALSE | GW15: FALSE | HA15: FALSE | HB15: FALSE | HC15: FALSE | HD15: FALSE | HH15: FALSE | HI15: FALSE | HJ15: FALSE | HK15: FALSE | HO15: FALSE | HP15: FALSE | HQ15: FALSE | HR15: FALSE | HV15: FALSE | HW15: FALSE | HX15: FALSE | HY15: FALSE | IC15: FALSE | ID15: FALSE | IE15: FALSE | IF15: FALSE | IJ15: FALSE | IK15: FALSE | IL15: FALSE | IM15: FALSE | IQ15: FALSE | IR15: FALSE | IS15: FALSE | IT15: FALSE
C16: 7 | F16: FALSE | G16: FALSE | H16: FALSE | I16: FALSE | M16: FALSE | N16: FALSE | O16: FALSE | P16: FALSE | T16: FALSE | U16: FALSE | V16: FALSE | W16: FALSE | AA16: FALSE | AB16: FALSE | AC16: FALSE | AD16: FALSE | AH16: FALSE | AI16: FALSE | AJ16: FALSE | AK16: FALSE | AO16: FALSE | AP16: FALSE | AQ16: FALSE | AR16: FALSE | AV16: FALSE | AW16: FALSE | AX16: FALSE | AY16: FALSE | BC16: FALSE | BD16: FALSE | BE16: FALSE | BF16: FALSE | BJ16: FALSE | BK16: FALSE | BL16: FALSE | BM16: FALSE | BQ16: FALSE | BR16: FALSE | BS16: FALSE | BT16: FALSE | BX16: FALSE | BY16: FALSE | BZ16: FALSE | CA16: FALSE | CE16: FALSE | CF16: FALSE | CG16: FALSE | CH16: FALSE | CL16: FALSE | CM16: FALSE | CN16: FALSE | CO16: FALSE | CS16: FALSE | CT16: FALSE | CU16: FALSE | CV16: FALSE | CZ16: FALSE | DA16: FALSE | DB16: FALSE | DC16: FALSE | DG16: FALSE | DH16: FALSE | DI16: FALSE | DJ16: FALSE | DN16: FALSE | DO16: FALSE | DP16: FALSE | DQ16: FALSE | DU16: FALSE | DV16: FALSE | DW16: FALSE | DX16: FALSE | EB16: FALSE | EC16: FALSE | ED16: FALSE | EE16: FALSE | EI16: FALSE | EJ16: FALSE | EK16: FALSE | EL16: FALSE | EP16: FALSE | EQ16: FALSE | ER16: FALSE | ES16: FALSE | EW16: FALSE | EX16: FALSE | EY16: FALSE | EZ16: FALSE | FD16: FALSE | FE16: FALSE | FF16: FALSE | FG16: FALSE | FK16: FALSE | FL16: FALSE | FM16: FALSE | FN16: FALSE | FR16: FALSE | FS16: FALSE | FT16: FALSE | FU16: FALSE | FY16: FALSE | FZ16: FALSE | GA16: FALSE | GB16: FALSE | GF16: FALSE | GG16: FALSE | GH16: FALSE | GI16: FALSE | GM16: FALSE | GN16: FALSE | GO16: FALSE | GP16: FALSE | GT16: FALSE | GU16: FALSE | GV16: FALSE | GW16: FALSE | HA16: FALSE | HB16: FALSE | HC16: FALSE | HD16: FALSE | HH16: FALSE | HI16: FALSE | HJ16: FALSE | HK16: FALSE | HO16: FALSE | HP16: FALSE | HQ16: FALSE | HR16: FALSE | HV16: FALSE | HW16: FALSE | HX16: FALSE | HY16: FALSE | IC16: FALSE | ID16: FALSE | IE16: FALSE | IF16: FALSE | IJ16: FALSE | IK16: FALSE | IL16: FALSE | IM16: FALSE | IQ16: FALSE | IR16: FALSE | IS16: FALSE | IT16: FALSE
C17: 8 | F17: FALSE | G17: FALSE | H17: FALSE | I17: FALSE | M17: FALSE | N17: FALSE | O17: FALSE | P17: FALSE | T17: FALSE | U17: FALSE | V17: FALSE | W17: FALSE | AA17: FALSE | AB17: FALSE | AC17: FALSE | AD17: FALSE | AH17: FALSE | AI17: FALSE | AJ17: FALSE | AK17: FALSE | AO17: FALSE | AP17: FALSE | AQ17: FALSE | AR17: FALSE | AV17: FALSE | AW17: FALSE | AX17: FALSE | AY17: FALSE | BC17: FALSE | BD17: FALSE | BE17: FALSE | BF17: FALSE | BJ17: FALSE | BK17: FALSE | BL17: FALSE | BM17: FALSE | BQ17: FALSE | BR17: FALSE | BS17: FALSE | BT17: FALSE | BX17: FALSE | BY17: FALSE | BZ17: FALSE | CA17: FALSE | CE17: FALSE | CF17: FALSE | CG17: FALSE | CH17: FALSE | CL17: FALSE | CM17: FALSE | CN17: FALSE | CO17: FALSE | CS17: FALSE | CT17: FALSE | CU17: FALSE | CV17: FALSE | CZ17: FALSE | DA17: FALSE | DB17: FALSE | DC17: FALSE | DG17: FALSE | DH17: FALSE | DI17: FALSE | DJ17: FALSE | DN17: FALSE | DO17: FALSE | DP17: FALSE | DQ17: FALSE | DU17: FALSE | DV17: FALSE | DW17: FALSE | DX17: FALSE | EB17: FALSE | EC17: FALSE | ED17: FALSE | EE17: FALSE | EI17: FALSE | EJ17: FALSE | EK17: FALSE | EL17: FALSE | EP17: FALSE | EQ17: FALSE | ER17: FALSE | ES17: FALSE | EW17: FALSE | EX17: FALSE | EY17: FALSE | EZ17: FALSE | FD17: FALSE | FE17: FALSE | FF17: FALSE | FG17: FALSE | FK17: FALSE | FL17: FALSE | FM17: FALSE | FN17: FALSE | FR17: FALSE | FS17: FALSE | FT17: FALSE | FU17: FALSE | FY17: FALSE | FZ17: FALSE | GA17: FALSE | GB17: FALSE | GF17: FALSE | GG17: FALSE | GH17: FALSE | GI17: FALSE | GM17: FALSE | GN17: FALSE | GO17: FALSE | GP17: FALSE | GT17: FALSE | GU17: FALSE | GV17: FALSE | GW17: FALSE | HA17: FALSE | HB17: FALSE | HC17: FALSE | HD17: FALSE | HH17: FALSE | HI17: FALSE | HJ17: FALSE | HK17: FALSE | HO17: FALSE | HP17: FALSE | HQ17: FALSE | HR17: FALSE | HV17: FALSE | HW17: FALSE | HX17: FALSE | HY17: FALSE | IC17: FALSE | ID17: FALSE | IE17: FALSE | IF17: FALSE | IJ17: FALSE | IK17: FALSE | IL17: FALSE | IM17: FALSE | IQ17: FALSE | IR17: FALSE | IS17: FALSE | IT17: FALSE
C18: 9 | F18: FALSE | G18: FALSE | H18: FALSE | I18: FALSE | M18: FALSE | N18: FALSE | O18: FALSE | P18: FALSE | T18: FALSE | U18: FALSE | V18: FALSE | W18: FALSE | AA18: FALSE | AB18: FALSE | AC18: FALSE | AD18: FALSE | AH18: FALSE | AI18: FALSE | AJ18: FALSE | AK18: FALSE | AO18: FALSE | AP18: FALSE | AQ18: FALSE | AR18: FALSE | AV18: FALSE | AW18: FALSE | AX18: FALSE | AY18: FALSE | BC18: FALSE | BD18: FALSE | BE18: FALSE | BF18: FALSE | BJ18: FALSE | BK18: FALSE | BL18: FALSE | BM18: FALSE | BQ18: FALSE | BR18: FALSE | BS18: FALSE | BT18: FALSE | BX18: FALSE | BY18: FALSE | BZ18: FALSE | CA18: FALSE | CE18: FALSE | CF18: FALSE | CG18: FALSE | CH18: FALSE | CL18: FALSE | CM18: FALSE | CN18: FALSE | CO18: FALSE | CS18: FALSE | CT18: FALSE | CU18: FALSE | CV18: FALSE | CZ18: FALSE | DA18: FALSE | DB18: FALSE | DC18: FALSE | DG18: FALSE | DH18: FALSE | DI18: FALSE | DJ18: FALSE | DN18: FALSE | DO18: FALSE | DP18: FALSE | DQ18: FALSE | DU18: FALSE | DV18: FALSE | DW18: FALSE | DX18: FALSE | EB18: FALSE | EC18: FALSE | ED18: FALSE | EE18: FALSE | EI18: FALSE | EJ18: FALSE | EK18: FALSE | EL18: FALSE | EP18: FALSE | EQ18: FALSE | ER18: FALSE | ES18: FALSE | EW18: FALSE | EX18: FALSE | EY18: FALSE | EZ18: FALSE | FD18: FALSE | FE18: FALSE | FF18: FALSE | FG18: FALSE | FK18: FALSE | FL18: FALSE | FM18: FALSE | FN18: FALSE | FR18: FALSE | FS18: FALSE | FT18: FALSE | FU18: FALSE | FY18: FALSE | FZ18: FALSE | GA18: FALSE | GB18: FALSE | GF18: FALSE | GG18: FALSE | GH18: FALSE | GI18: FALSE | GM18: FALSE | GN18: FALSE | GO18: FALSE | GP18: FALSE | GT18: FALSE | GU18: FALSE | GV18: FALSE | GW18: FALSE | HA18: FALSE | HB18: FALSE | HC18: FALSE | HD18: FALSE | HH18: FALSE | HI18: FALSE | HJ18: FALSE | HK18: FALSE | HO18: FALSE | HP18: FALSE | HQ18: FALSE | HR18: FALSE | HV18: FALSE | HW18: FALSE | HX18: FALSE | HY18: FALSE | IC18: FALSE | ID18: FALSE | IE18: FALSE | IF18: FALSE | IJ18: FALSE | IK18: FALSE | IL18: FALSE | IM18: FALSE | IQ18: FALSE | IR18: FALSE | IS18: FALSE | IT18: FALSE
C19: 10 | F19: FALSE | G19: FALSE | H19: FALSE | I19: FALSE | M19: FALSE | N19: FALSE | O19: FALSE | P19: FALSE | T19: FALSE | U19: FALSE | V19: FALSE | W19: FALSE | AA19: FALSE | AB19: FALSE | AC19: FALSE | AD19: FALSE | AH19: FALSE | AI19: FALSE | AJ19: FALSE | AK19: FALSE | AO19: FALSE | AP19: FALSE | AQ19: FALSE | AR19: FALSE | AV19: FALSE | AW19: FALSE | AX19: FALSE | AY19: FALSE | BC19: FALSE | BD19: FALSE | BE19: FALSE | BF19: FALSE | BJ19: FALSE | BK19: FALSE | BL19: FALSE | BM19: FALSE | BQ19: FALSE | BR19: FALSE | BS19: FALSE | BT19: FALSE | BX19: FALSE | BY19: FALSE | BZ19: FALSE | CA19: FALSE | CE19: FALSE | CF19: FALSE | CG19: FALSE | CH19: FALSE | CL19: FALSE | CM19: FALSE | CN19: FALSE | CO19: FALSE | CS19: FALSE | CT19: FALSE | CU19: FALSE | CV19: FALSE | CZ19: FALSE | DA19: FALSE | DB19: FALSE | DC19: FALSE | DG19: FALSE | DH19: FALSE | DI19: FALSE | DJ19: FALSE | DN19: FALSE | DO19: FALSE | DP19: FALSE | DQ19: FALSE | DU19: FALSE | DV19: FALSE | DW19: FALSE | DX19: FALSE | EB19: FALSE | EC19: FALSE | ED19: FALSE | EE19: FALSE | EI19: FALSE | EJ19: FALSE | EK19: FALSE | EL19: FALSE | EP19: FALSE | EQ19: FALSE | ER19: FALSE | ES19: FALSE | EW19: FALSE | EX19: FALSE | EY19: FALSE | EZ19: FALSE | FD19: FALSE | FE19: FALSE | FF19: FALSE | FG19: FALSE | FK19: FALSE | FL19: FALSE | FM19: FALSE | FN19: FALSE | FR19: FALSE | FS19: FALSE | FT19: FALSE | FU19: FALSE | FY19: FALSE | FZ19: FALSE | GA19: FALSE | GB19: FALSE | GF19: FALSE | GG19: FALSE | GH19: FALSE | GI19: FALSE | GM19: FALSE | GN19: FALSE | GO19: FALSE | GP19: FALSE | GT19: FALSE | GU19: FALSE | GV19: FALSE | GW19: FALSE | HA19: FALSE | HB19: FALSE | HC19: FALSE | HD19: FALSE | HH19: FALSE | HI19: FALSE | HJ19: FALSE | HK19: FALSE | HO19: FALSE | HP19: FALSE | HQ19: FALSE | HR19: FALSE | HV19: FALSE | HW19: FALSE | HX19: FALSE | HY19: FALSE | IC19: FALSE | ID19: FALSE | IE19: FALSE | IF19: FALSE | IJ19: FALSE | IK19: FALSE | IL19: FALSE | IM19: FALSE | IQ19: FALSE | IR19: FALSE | IS19: FALSE | IT19: FALSE
C20: 11 | F20: FALSE | G20: FALSE | H20: FALSE | I20: FALSE | M20: FALSE | N20: FALSE | O20: FALSE | P20: FALSE | T20: FALSE | U20: FALSE | V20: FALSE | W20: FALSE | AA20: FALSE | AB20: FALSE | AC20: FALSE | AD20: FALSE | AH20: FALSE | AI20: FALSE | AJ20: FALSE | AK20: FALSE | AO20: FALSE | AP20: FALSE | AQ20: FALSE | AR20: FALSE | AV20: FALSE | AW20: FALSE | AX20: FALSE | AY20: FALSE | BC20: FALSE | BD20: FALSE | BE20: FALSE | BF20: FALSE | BJ20: FALSE | BK20: FALSE | BL20: FALSE | BM20: FALSE | BQ20: FALSE | BR20: FALSE | BS20: FALSE | BT20: FALSE | BX20: FALSE | BY20: FALSE | BZ20: FALSE | CA20: FALSE | CE20: FALSE | CF20: FALSE | CG20: FALSE | CH20: FALSE | CL20: FALSE | CM20: FALSE | CN20: FALSE | CO20: FALSE | CS20: FALSE | CT20: FALSE | CU20: FALSE | CV20: FALSE | CZ20: FALSE | DA20: FALSE | DB20: FALSE | DC20: FALSE | DG20: FALSE | DH20: FALSE | DI20: FALSE | DJ20: FALSE | DN20: FALSE | DO20: FALSE | DP20: FALSE | DQ20: FALSE | DU20: FALSE | DV20: FALSE | DW20: FALSE | DX20: FALSE | EB20: FALSE | EC20: FALSE | ED20: FALSE | EE20: FALSE | EI20: FALSE | EJ20: FALSE | EK20: FALSE | EL20: FALSE | EP20: FALSE | EQ20: FALSE | ER20: FALSE | ES20: FALSE | EW20: FALSE | EX20: FALSE | EY20: FALSE | EZ20: FALSE | FD20: FALSE | FE20: FALSE | FF20: FALSE | FG20: FALSE | FK20: FALSE | FL20: FALSE | FM20: FALSE | FN20: FALSE | FR20: FALSE | FS20: FALSE | FT20: FALSE | FU20: FALSE | FY20: FALSE | FZ20: FALSE | GA20: FALSE | GB20: FALSE | GF20: FALSE | GG20: FALSE | GH20: FALSE | GI20: FALSE | GM20: FALSE | GN20: FALSE | GO20: FALSE | GP20: FALSE | GT20: FALSE | GU20: FALSE | GV20: FALSE | GW20: FALSE | HA20: FALSE | HB20: FALSE | HC20: FALSE | HD20: FALSE | HH20: FALSE | HI20: FALSE | HJ20: FALSE | HK20: FALSE | HO20: FALSE | HP20: FALSE | HQ20: FALSE | HR20: FALSE | HV20: FALSE | HW20: FALSE | HX20: FALSE | HY20: FALSE | IC20: FALSE | ID20: FALSE | IE20: FALSE | IF20: FALSE | IJ20: FALSE | IK20: FALSE | IL20: FALSE | IM20: FALSE | IQ20: FALSE | IR20: FALSE | IS20: FALSE | IT20: FALSE
C21: 12 | F21: FALSE | G21: FALSE | H21: FALSE | I21: FALSE | M21: FALSE | N21: FALSE | O21: FALSE | P21: FALSE | T21: FALSE | U21: FALSE | V21: FALSE | W21: FALSE | AA21: FALSE | AB21: FALSE | AC21: FALSE | AD21: FALSE | AH21: FALSE | AI21: FALSE | AJ21: FALSE | AK21: FALSE | AO21: FALSE | AP21: FALSE | AQ21: FALSE | AR21: FALSE | AV21: FALSE | AW21: FALSE | AX21: FALSE | AY21: FALSE | BC21: FALSE | BD21: FALSE | BE21: FALSE | BF21: FALSE | BJ21: FALSE | BK21: FALSE | BL21: FALSE | BM21: FALSE | BQ21: FALSE | BR21: FALSE | BS21: FALSE | BT21: FALSE | BX21: FALSE | BY21: FALSE | BZ21: FALSE | CA21: FALSE | CE21: FALSE | CF21: FALSE | CG21: FALSE | CH21: FALSE | CL21: FALSE | CM21: FALSE | CN21: FALSE | CO21: FALSE | CS21: FALSE | CT21: FALSE | CU21: FALSE | CV21: FALSE | CZ21: FALSE | DA21: FALSE | DB21: FALSE | DC21: FALSE | DG21: FALSE | DH21: FALSE | DI21: FALSE | DJ21: FALSE | DN21: FALSE | DO21: FALSE | DP21: FALSE | DQ21: FALSE | DU21: FALSE | DV21: FALSE | DW21: FALSE | DX21: FALSE | EB21: FALSE | EC21: FALSE | ED21: FALSE | EE21: FALSE | EI21: FALSE | EJ21: FALSE | EK21: FALSE | EL21: FALSE | EP21: FALSE | EQ21: FALSE | ER21: FALSE | ES21: FALSE | EW21: FALSE | EX21: FALSE | EY21: FALSE | EZ21: FALSE | FD21: FALSE | FE21: FALSE | FF21: FALSE | FG21: FALSE | FK21: FALSE | FL21: FALSE | FM21: FALSE | FN21: FALSE | FR21: FALSE | FS21: FALSE | FT21: FALSE | FU21: FALSE | FY21: FALSE | FZ21: FALSE | GA21: FALSE | GB21: FALSE | GF21: FALSE | GG21: FALSE | GH21: FALSE | GI21: FALSE | GM21: FALSE | GN21: FALSE | GO21: FALSE | GP21: FALSE | GT21: FALSE | GU21: FALSE | GV21: FALSE | GW21: FALSE | HA21: FALSE | HB21: FALSE | HC21: FALSE | HD21: FALSE | HH21: FALSE | HI21: FALSE | HJ21: FALSE | HK21: FALSE | HO21: FALSE | HP21: FALSE | HQ21: FALSE | HR21: FALSE | HV21: FALSE | HW21: FALSE | HX21: FALSE | HY21: FALSE | IC21: FALSE | ID21: FALSE | IE21: FALSE | IF21: FALSE | IJ21: FALSE | IK21: FALSE | IL21: FALSE | IM21: FALSE | IQ21: FALSE | IR21: FALSE | IS21: FALSE | IT21: FALSE
... C24: 15 | F24: FALSE | G24: FALSE | H24: FALSE | I24: FALSE | M24: FALSE | N24: FALSE | O24: FALSE | P24: FALSE | T24: FALSE | U24: FALSE | V24: FALSE | W24: FALSE | AA24: FALSE | AB24: FALSE | AC24: FALSE | AD24: FALSE | AH24: FALSE | AI24: FALSE | AJ24: FALSE | AK24: FALSE | AO24: FALSE | AP24: FALSE | AQ24: FALSE | AR24: FALSE | AV24: FALSE | AW24: FALSE | AX24: FALSE | AY24: FALSE | BC24: FALSE | BD24: FALSE | BE24: FALSE | BF24: FALSE | BJ24: FALSE | BK24: FALSE | BL24: FALSE | BM24: FALSE | BQ24: FALSE | BR24: FALSE | BS24: FALSE | BT24: FALSE | BX24: FALSE | BY24: FALSE | BZ24: FALSE | CA24: FALSE | CE24: FALSE | CF24: FALSE | CG24: FALSE | CH24: FALSE | CL24: FALSE | CM24: FALSE | CN24: FALSE | CO24: FALSE | CS24: FALSE | CT24: FALSE | CU24: FALSE | CV24: FALSE | CZ24: FALSE | DA24: FALSE | DB24: FALSE | DC24: FALSE | DG24: FALSE | DH24: FALSE | DI24: FALSE | DJ24: FALSE | DN24: FALSE | DO24: FALSE | DP24: FALSE | DQ24: FALSE | DU24: FALSE | DV24: FALSE | DW24: FALSE | DX24: FALSE | EB24: FALSE | EC24: FALSE | ED24: FALSE | EE24: FALSE | EI24: FALSE | EJ24: FALSE | EK24: FALSE | EL24: FALSE | EP24: FALSE | EQ24: FALSE | ER24: FALSE | ES24: FALSE | EW24: FALSE | EX24: FALSE | EY24: FALSE | EZ24: FALSE | FD24: FALSE | FE24: FALSE | FF24: FALSE | FG24: FALSE | FK24: FALSE | FL24: FALSE | FM24: FALSE | FN24: FALSE | FR24: FALSE | FS24: FALSE | FT24: FALSE | FU24: FALSE | FY24: FALSE | FZ24: FALSE | GA24: FALSE | GB24: FALSE | GF24: FALSE | GG24: FALSE | GH24: FALSE | GI24: FALSE | GM24: FALSE | GN24: FALSE | GO24: FALSE | GP24: FALSE | GT24: FALSE | GU24: FALSE | GV24: FALSE | GW24: FALSE | HA24: FALSE | HB24: FALSE | HC24: FALSE | HD24: FALSE | HH24: FALSE | HI24: FALSE | HJ24: FALSE | HK24: FALSE | HO24: FALSE | HP24: FALSE | HQ24: FALSE | HR24: FALSE | HV24: FALSE | HW24: FALSE | HX24: FALSE | HY24: FALSE | IC24: FALSE | ID24: FALSE | IE24: FALSE | IF24: FALSE | IJ24: FALSE | IK24: FALSE | IL24: FALSE | IM24: FALSE | IQ24: FALSE | IR24: FALSE | IS24: FALSE | IT24: FALSE
